Workbook

Sheet Respuestas de formulario 1
A1: Marca temporal | B1: Fecha | C1: Mes de Análisis | D1: Tipo de Registro | E1: Categoría / Fuente | F1: Descripción / Detalle | G1: Monto ($) | H1: Medio de Pago
H2: =IF(D2="Gasto", IFERROR(VLOOKUP(E2, Config!$F$6:$G$29, 2, FALSE), ""), "")
A3: 46218.838 | B3: 46156 | C3: Mayo | D3: Gasto | E3: Otros Gastos | F3: Devolver plata Tomas | G3: 1000000 | H3: =IF(D3="Gasto", IFERROR(VLOOKUP(E3, Config!$F$6:$G$29, 2, FALSE), ""), "") -> Variable
A4: 46218.839 | B4: 46209 | C4: Julio | D4: Gasto | E4: Otros Gastos | F4: PAGO TC MIA | G4: 1890000 | H4: =IF(D4="Gasto", IFERROR(VLOOKUP(E4, Config!$F$6:$G$29, 2, FALSE), ""), "") -> Variable
A5: 46218.839 | B5: 46209 | C5: Julio | D5: Gasto | E5: Otros Gastos | F5: PAGO TC ROBY | G5: 181000 | H5: =IF(D5="Gasto", IFERROR(VLOOKUP(E5, Config!$F$6:$G$29, 2, FALSE), ""), "") -> Variable
A6: 46218.84 | B6: 46209 | C6: Julio | D6: Gasto | E6: Otros Gastos | F6: PAGO TC ML | G6: 196000 | H6: =IF(D6="Gasto", IFERROR(VLOOKUP(E6, Config!$F$6:$G$29, 2, FALSE), ""), "") -> Variable
A7: 46218.841 | B7: 46216 | C7: Julio | D7: Gasto | E7: Otros Gastos | F7: PAGO PRESTAMO ML | G7: 167619 | H7: =IF(D7="Gasto", IFERROR(VLOOKUP(E7, Config!$F$6:$G$29, 2, FALSE), ""), "") -> Variable
A8: 46219.252 | B8: 46219 | C8: Julio | D8: Gasto | E8: Otros Gastos | F8: Criollos resi | G8: 3000 | H8: Efectivo/MP
A9: 46219.253 | B9: 46218 | C9: Julio | D9: Gasto | E9: Transporte / Auto | F9: Nafta 20k descuento MODO | G9: 55000 | H9: Tarjeta de Crédito
A10: 46219.274 | B10: 46219 | C10: Julio | D10: Gasto | E10: Supermercado | F10: Changomas con descuento 25k | G10: 135000 | H10: Tarjeta de Crédito
A11: 46219.277 | B11: 46219 | C11: Julio | D11: Gasto | E11: Compras Online / Impulsivas | F11: Termos Amazon | G11: 167500 | H11: Tarjeta de Crédito
A12: 46219.278 | B12: 46219 | C12: Julio | D12: Gasto | E12: Compras Online / Impulsivas | F12: Cuotas de cargador, celular lela, auriculares | G12: 30500 | H12: Tarjeta de Crédito
A13: 46219.28 | B13: 46219 | C13: Julio | D13: Gasto | E13: Delivery | F13: Delivery mio y uno que pidio el tomi sin querer | G13: 43000 | H13: Tarjeta de Crédito
A14: 46219.365 | B14: 46218 | C14: Julio | D14: Gasto | E14: Salidas / Gastronomía | F14: Huevos | G14: 12000 | H14: Efectivo/MP
A15: 46219.367 | B15: 46218 | C15: Julio | D15: Gasto | E15: Otros Gastos | F15: Psico | G15: 37000 | H15: Efectivo/MP
A16: 46219.367 | B16: 46218 | C16: Julio | D16: Gasto | E16: Otros Gastos | F16: Cumple Cinthia | G16: 10000 | H16: Efectivo/MP
A17: 46219.367 | B17: 46215 | C17: Julio | D17: Gasto | E17: Salidas / Gastronomía | F17: Pizzas a la Maca | G17: 44000 | H17: Efectivo/MP
A18: 46219.368 | B18: 46212 | C18: Julio | D18: Gasto | E18: Salidas / Gastronomía | F18: Dietetica | G18: 31000 | H18: Efectivo/MP
A19: 46219.369 | B19: 46213 | C19: Julio | D19: Gasto | E19: Salidas / Gastronomía | F19: Empanadas de la reina con la piki | G19: 17000 | H19: Efectivo/MP
A20: 46219.37 | B20: 46204 | C20: Julio | D20: Gasto | E20: Otros Gastos | F20: Maderas Juan | G20: 135750 | H20: Efectivo/MP
A21: 46219.371 | B21: 46204 | C21: Julio | D21: Gasto | E21: Monotributo | G21: 33000 | H21: Efectivo/MP
A22: 46219.372 | B22: 46219 | C22: Julio | D22: Ingreso | E22: Otros ingresos variables | F22: Plan canje Samsung | G22: 103000 | H22: Efectivo/MP
A23: 46219.471 | B23: 46219 | C23: Julio | D23: Gasto | E23: Telefonía | G23: 23600 | H23: Tarjeta de Crédito
A24: 46221.358 | B24: 46221 | C24: Julio | D24: Gasto | E24: Delivery | F24: Lomitos con la piki | G24: 19250 | H24: Efectivo/MP
A25: 46221.396 | B25: 45856 | C25: Julio | D25: Gasto | E25: Otros Gastos | F25: Delantal y pimentero La Cautiva | G25: 86300 | H25: Efectivo/MP
A26: 46221.575 | B26: 46192 | C26: Julio | D26: Gasto | E26: Salidas / Gastronomía | F26: Verdulería para comida con autorespeto | G26: 13468 | H26: Efectivo/MP
A27: 46223.441 | B27: 46223 | C27: Julio | D27: Gasto | E27: Otros Gastos | F27: Cumple Lantu con las chicas | G27: 3800 | H27: Efectivo/MP
A28: 46224.477 | B28: 46224 | C28: Julio | D28: Gasto | E28: Compras Online / Impulsivas | F28: Viaje Brasil con el Tomi en octubre | G28: 1936500 | H28: Tarjeta de Crédito
A29: 46225.182 | B29: 46221 | C29: Julio | D29: Gasto | E29: Profesional (Colegiatura) | F29: Cuota colegio junio | G29: 38340 | H29: Tarjeta de Crédito
A30: 46225.183 | B30: 46221 | C30: Julio | D30: Gasto | E30: Salidas / Gastronomía | F30: Merienda con el Tomi | G30: 28000 | H30: Tarjeta de Crédito
A31: 46225.184 | B31: 46220 | C31: Julio | D31: Gasto | E31: Internet | F31: Airsat Julio 26 | G31: 37500 | H31: Tarjeta de Crédito
A32: 46225.185 | B32: 46219 | C32: Julio | D32: Gasto | E32: Otros Gastos | F32: Silent Hill 2 xbox | G32: 33000 | H32: Tarjeta de Crédito
A33: 46225.188 | B33: 46224 | C33: Julio | D33: Gasto | E33: Prepaga | F33: Sancor | G33: 171607 | H33: Tarjeta de Crédito
A34: 46243.658 | B34: 46224 | C34: Julio | D34: Gasto | E34: Compras Online / Impulsivas | F34: VIAJE RIO AMBOS | G34: 1928880 | H34: Tarjeta de Crédito
A35: 46243.66 | B35: 46217 | C35: Julio | D35: Gasto | E35: Compras Online / Impulsivas | F35: Compra ML varias cositas 1 | G35: 236780 | H35: Tarjeta de Crédito
... A47: 46243.671 | B47: 46241 | C47: Agosto | D47: Gasto | E47: Salidas / Gastronomía | F47: desayuno en MC congreso infecto | G47: 5200 | H47: Tarjeta de Crédito
A48: 46243.673 | B48: 46235 | C48: Agosto | D48: Ingreso | E48: Residencia (Epidemiología) | G48: 1821000 | H48: Efectivo/MP
A49: 46243.673 | B49: 46235 | C49: Agosto | D49: Ingreso | E49: Laboratorio SEVEDIC | G49: 950000 | H49: Efectivo/MP
A50: 46243.674 | B50: 46237 | C50: Agosto | D50: Gasto | E50: Tarjeta | F50: PAGO TARJETA MACRO (parte de pesos sin impuestos y los dolares que debía con stop debit) | G50: 2440000 | H50: Efectivo/MP
A51: 46243.675 | B51: 46241 | C51: Agosto | D51: Gasto | E51: Transporte / Auto | F51: Arreglo grande suspensione aceite y demás pero en 6 cuotas | G51: 1400000 | H51: Tarjeta de Crédito
...

Sheet Léame
A1: PLANIFICADOR FINANCIERO — FUSIÓN Y CAMBIOS
A3: 1. Qué se fusionó
A4: Se tomó la arquitectura del archivo de la otra IA (tabla continua de Ingresos/Gastos + Dashboard con SUMIF/SUMIFS) porque es la que soporta automatización con Google Forms y análisis anual sin duplicar datos.
A6: Se agregó el detalle de categorías y el enfoque de seguimiento mensual que veníamos usando en nuestra planilla anterior.
A8: 2. Cambios sobre el archivo original de la otra IA
A9: • Regla de distribución: se cambió de 45/25/30 a 50/30/20 (Necesidades/Deseos/Ahorro), que fue tu pedido original. Editable en Config!B6:B8.
A10: • Categorías de gastos: se ampliaron de 12 a 24, separando Luz/Agua/Gas/Internet/Telefonía (antes 'Servicios' único) y agregando Prepaga, Seguro Auto, Seguros Adicionales, Impuestos y Costos TC, Compras Online/Impulsivas, Delivery, Educación/Cursos y Profesional. Ver Config!F6:G29.
A12: • Fuentes de ingreso: se ajustaron a tu esquema real — Residencia (Epidemiología), Centro de Castración de Saldán, Laboratorio SEVEDIC, Otros ingresos variables. Ver Config!D6:D9.
A14: 3. Historial cargado (Abril–Junio 2026)
A15: Se cargaron 118 transacciones reales extraídas de tus 3 resúmenes de Visa (cierres 23-Abr, 21-May y 25-Jun) en la hoja Gastos, ya categorizadas con el esquema nuevo.
A17: Supuesto declarado: los consumos en USD (Google One, Steam, Amazon, etc.) se agruparon en una sola fila 'Suscripciones digitales USD' por mes, convertida a un dólar tarjeta de referencia (~$1.956). Es un monto chico (equivalente a US$12-26/mes) así que el redondeo no distorsiona el análisis, pero si querés precisión exacta, editá esas 2 filas puntuales en Gastos.
A19: No se cargaron Ingresos históricos de Abril-Junio porque no tengo esos montos exactos mes a mes (solo el ingreso actual de Julio). Si querés el historial completo, pasame los montos y los cargo.
... A45: Panel nuevo y separado del análisis por categoría. Registra cuándo realmente pagaste el resumen de la tarjeta (no cuándo compraste), para saber cuánta plata real tuviste disponible cada mes. Las columnas C (Pago Resumen TC) y D (Otros gastos fuera de TC) son manuales — cargalas vos mismo con el monto real que debitaste ese mes. B4 no aplica acá: esta tabla siempre muestra los 12 meses juntos.

Sheet Config
A1: CONFIGURACIÓN FINANCIERA
A2: Reglas de presupuesto, fuentes de ingreso y categorías.
A4: Regla de Distribución | D4: Fuentes de Ingreso | F4: Categorías de Gastos | I4: Meses
A5: Tipo de Uso | B5: Porcentaje | D5: Fuente | F5: Categoría | G5: Tipo | I5: Mes
A6: Gastos Fijos (Necesidades) | B6: 0.5 | D6: Residencia (Epidemiología) | F6: Expensas | G6: Fijo | I6: Enero
A7: Gastos Variables (Deseos) | B7: 0.3 | D7: Centro de Castración de Saldán | F7: Prepaga | G7: Fijo | I7: Febrero
A8: Ahorro / Inversión | B8: 0.2 | D8: Laboratorio SEVEDIC | F8: Monotributo | G8: Fijo | I8: Marzo
A9: Nota: se fijó 50/30/20 (pedido original), no el 45/25/30 del otro archivo. | D9: Otros ingresos variables | F9: Seguro Auto | G9: Fijo | I9: Abril
D10: CDC/Hospital | F10: Seguros Adicionales | G10: Fijo | I10: Mayo
F11: Luz | G11: Fijo | I11: Junio
F12: Agua | G12: Fijo | I12: Julio
F13: Gas | G13: Fijo | I13: Agosto
F14: Internet | G14: Fijo | I14: Septiembre
F15: Telefonía | G15: Fijo | I15: Octubre
F16: Transporte / Auto | G16: Fijo | I16: Noviembre
F17: Supermercado | G17: Fijo | I17: Diciembre
F18: Mascota (Chancho) | G18: Fijo
F19: Gimnasio / CrossFit | G19: Fijo
F20: Salud / Farmacia | G20: Fijo
F21: Profesional (Colegiatura) | G21: Fijo
F22: Impuestos y Costos TC | G22: Fijo
F23: Delivery | G23: Variable
F24: Salidas / Gastronomía | G24: Variable
F25: Compras Online / Impulsivas | G25: Variable
F26: Suscripciones | G26: Variable
F27: Educación / Cursos | G27: Variable
F28: Indumentaria | G28: Variable
F29: Otros Gastos | G29: Variable
F30: Tarjeta

Sheet Ingresos
A1: REGISTRO DE INGRESOS CONTINUO
A2: Cargue todos sus ingresos aquí de forma corrida para todo el año.
A4: Fecha | B4: Mes | C4: Fuente | D4: Detalle | E4: Monto ($)
A5: 46113 | B5: Abril | C5: Laboratorio | E5: 750000
A6: 46122 | B6: Abril | C6: CDC | E6: 1155000
A7: 46144 | B7: Mayo | C7: Laboratorio | E7: 825000
A8: 46144 | B8: Mayo | C8: CDC | E8: 1155000
A9: 46144 | B9: Mayo | C9: Saldan | E9: 300000
A10: 46172 | B10: Junio | C10: Laboratorio | E10: 850000
A11: 46172 | B11: Junio | C11: CDC | E11: 1155000
A12: 46172 | B12: Junio | C12: Saldan | E12: 300000
A13: 46174 | B13: Julio | C13: Laboratorio | D13: sueldo + aguinaldo | E13: 1275000
A14: 46174 | B14: Julio | C14: CDC | E14: 575000
A15: 46174 | B15: Julio | C15: Saldan | E15: 300000
A16: 46174 | B16: Julio | C16: Residencia | D16: Sueldo + aguinaldo | E16: 1936930
A17: 46219 | B17: Julio | C17: Otros ingresos variables | D17: Plan canje Samsung | E17: 103000
A18: 46235 | B18: Agosto | C18: Residencia (Epidemiología) | E18: 1821000
A19: 46235 | B19: Agosto | C19: Laboratorio SEVEDIC | E19: 950000

Sheet Gastos
A1: 5
A2: Cargue todos sus gastos diarios de corrido. El 'Tipo' se asigna de manera automática.
A4: Fecha | B4: Mes | C4: Descripción | D4: Categoría | E4: Tipo | F4: Monto ($) | G4: Medio de Pago
A5: 46008 | B5: Abril | C5: Mercado Libre cuota 5/6 | D5: Compras Online / Impulsivas | E5: =IF(ISBLANK(D5), "", VLOOKUP(D5, Config!$F$6:$G$29, 2, FALSE())) -> Variable | F5: 11915.66 | G5: Tarjeta de Crédito
A6: 46048 | B6: Abril | C6: Municipalidad Córdoba cuota 3/3 | D6: Impuestos y Costos TC | E6: =IF(ISBLANK(D6), "", VLOOKUP(D6, Config!$F$6:$G$29, 2, FALSE())) -> Fijo | F6: 27005.25 | G6: Tarjeta de Crédito
A7: 46049 | B7: Abril | C7: Municipalidad Córdoba cuota 3/3 | D7: Impuestos y Costos TC | E7: =IF(ISBLANK(D7), "", VLOOKUP(D7, Config!$F$6:$G$29, 2, FALSE())) -> Fijo | F7: 97290 | G7: Tarjeta de Crédito
A8: 46062 | B8: Abril | C8: Fravega cuota 3/3 | D8: Compras Online / Impulsivas | E8: =IF(ISBLANK(D8), "", VLOOKUP(D8, Config!$F$6:$G$29, 2, FALSE())) -> Variable | F8: 199999.66 | G8: Tarjeta de Crédito
A9: 46092 | B9: Abril | C9: Samsung.com cuota 2/9 | D9: Compras Online / Impulsivas | E9: =IF(ISBLANK(D9), "", VLOOKUP(D9, Config!$F$6:$G$29, 2, FALSE())) -> Variable | F9: 39999.88 | G9: Tarjeta de Crédito
A10: 46092 | B10: Abril | C10: Samsung.com cuota 3/9 | D10: Compras Online / Impulsivas | E10: =IF(ISBLANK(D10), "", VLOOKUP(D10, Config!$F$6:$G$29, 2, FALSE())) -> Variable | F10: 39999.88 | G10: Tarjeta de Crédito
A11: 46092 | B11: Abril | C11: Samsung.com cuota 4/9 | D11: Compras Online / Impulsivas | E11: =IF(ISBLANK(D11), "", VLOOKUP(D11, Config!$F$6:$G$29, 2, FALSE())) -> Variable | F11: 39999.88 | G11: Tarjeta de Crédito
A12: 46092 | B12: Abril | C12: Samsung.com cuota 5/9 | D12: Compras Online / Impulsivas | E12: =IF(ISBLANK(D12), "", VLOOKUP(D12, Config!$F$6:$G$29, 2, FALSE())) -> Variable | F12: 39999.88 | G12: Tarjeta de Crédito
A13: 46092 | B13: Abril | C13: Samsung.com cuota 6/9 | D13: Compras Online / Impulsivas | E13: =IF(ISBLANK(D13), "", VLOOKUP(D13, Config!$F$6:$G$29, 2, FALSE())) -> Variable | F13: 39999.88 | G13: Tarjeta de Crédito
A14: 46092 | B14: Abril | C14: Samsung.com cuota 7/9 | D14: Compras Online / Impulsivas | E14: =IF(ISBLANK(D14), "", VLOOKUP(D14, Config!$F$6:$G$29, 2, FALSE())) -> Variable | F14: 39999.88 | G14: Tarjeta de Crédito
A15: 46092 | B15: Abril | C15: Samsung.com cuota 8/9 | D15: Compras Online / Impulsivas | E15: =IF(ISBLANK(D15), "", VLOOKUP(D15, Config!$F$6:$G$29, 2, FALSE())) -> Variable | F15: 39999.88 | G15: Tarjeta de Crédito
A16: 46092 | B16: Abril | C16: Samsung.com cuota 9/9 | D16: Compras Online / Impulsivas | E16: =IF(ISBLANK(D16), "", VLOOKUP(D16, Config!$F$6:$G$29, 2, FALSE())) -> Variable | F16: 39999.88 | G16: Tarjeta de Crédito
... A123: 46198 | B123: Junio | C123: Suscripciones digitales USD (Google/Steam, ref. dólar tarjeta) | D123: Suscripciones | E123: =IF(ISBLANK(D123), "", VLOOKUP(D123, Config!$F$6:$G$29, 2, FALSE())) -> Variable | F123: 40333 | G123: Tarjeta de Crédito
A124: 46209 | B124: Julio | C124: PAGO TC MIA | D124: Tarjeta | E124: =IF(ISBLANK(D124), "", VLOOKUP(D124, Config!$F$6:$G$30, 2, FALSE())) | F124: 1890000 | G124: Efectivo/MP
A125: 46209 | B125: Julio | C125: PAGO TC ROBY | D125: Tarjeta | E125: =IF(ISBLANK(D125), "", VLOOKUP(D125, Config!$F$6:$G$30, 2, FALSE())) | F125: 181000 | G125: Efectivo/MP
A126: 46209 | B126: Julio | C126: PAGO TC ML | D126: Tarjeta | E126: =IF(ISBLANK(D126), "", VLOOKUP(D126, Config!$F$6:$G$30, 2, FALSE())) | F126: 196000 | G126: Efectivo/MP
A127: 46216 | B127: Julio | C127: PAGO PRESTAMO ML | D127: Tarjeta | E127: =IF(ISBLANK(D127), "", VLOOKUP(D127, Config!$F$6:$G$30, 2, FALSE())) | F127: 167619 | G127: Efectivo/MP
A128: 46219 | B128: Julio | C128: Criollos resi | D128: Otros Gastos | E128: =IF(ISBLANK(D128), "", VLOOKUP(D128, Config!$F$6:$G$30, 2, FALSE())) -> Variable | F128: 3000 | G128: Efectivo/MP
A129: 46218 | B129: Julio | C129: Nafta 20k descuento MODO | D129: Transporte / Auto | E129: =IF(ISBLANK(D129), "", VLOOKUP(D129, Config!$F$6:$G$30, 2, FALSE())) -> Fijo | F129: 55000 | G129: Tarjeta de Crédito
A130: 46219 | B130: Julio | C130: Changomas con descuento 25k | D130: Supermercado | E130: =IF(ISBLANK(D130), "", VLOOKUP(D130, Config!$F$6:$G$30, 2, FALSE())) -> Fijo | F130: 135000 | G130: Tarjeta de Crédito
A131: 46219 | B131: Julio | C131: Termos Amazon | D131: Compras Online / Impulsivas | E131: =IF(ISBLANK(D131), "", VLOOKUP(D131, Config!$F$6:$G$30, 2, FALSE())) -> Variable | F131: 167500 | G131: Tarjeta de Crédito
A132: 46219 | B132: Julio | C132: Cuotas de cargador, celular lela, auriculares | D132: Compras Online / Impulsivas | E132: =IF(ISBLANK(D132), "", VLOOKUP(D132, Config!$F$6:$G$30, 2, FALSE())) -> Variable | F132: 30500 | G132: Tarjeta de Crédito
A133: 46219 | B133: Julio | C133: Delivery mio y uno que pidio el tomi sin querer | D133: Delivery | E133: =IF(ISBLANK(D133), "", VLOOKUP(D133, Config!$F$6:$G$30, 2, FALSE())) -> Variable | F133: 43000 | G133: Tarjeta de Crédito
A134: 46218 | B134: Julio | C134: Huevos | D134: Salidas / Gastronomía | E134: =IF(ISBLANK(D134), "", VLOOKUP(D134, Config!$F$6:$G$30, 2, FALSE())) -> Variable | F134: 12000 | G134: Efectivo/MP
A135: 46218 | B135: Julio | C135: Psico | D135: Otros Gastos | E135: =IF(ISBLANK(D135), "", VLOOKUP(D135, Config!$F$6:$G$30, 2, FALSE())) -> Variable | F135: 37000 | G135: Efectivo/MP
... A140: 46204 | B140: Julio | C140: Maderas Juan | D140: Otros Gastos | E140: =IF(ISBLANK(D140), "", VLOOKUP(D140, Config!$F$6:$G$30, 2, FALSE())) -> Variable | F140: 135750 | G140: Efectivo/MP
A141: 46204 | B141: Julio | D141: Monotributo | E141: =IF(ISBLANK(D141), "", VLOOKUP(D141, Config!$F$6:$G$30, 2, FALSE())) -> Fijo | F141: 33000 | G141: Efectivo/MP
A142: 46219 | B142: Julio | D142: Telefonía | E142: =IF(ISBLANK(D142), "", VLOOKUP(D142, Config!$F$6:$G$30, 2, FALSE())) -> Fijo | F142: 23600 | G142: Tarjeta de Crédito
A143: 46221 | B143: Julio | C143: Lomitos con la piki | D143: Delivery | E143: =IF(ISBLANK(D143), "", VLOOKUP(D143, Config!$F$6:$G$30, 2, FALSE())) -> Variable | F143: 19250 | G143: Efectivo/MP
A144: 45856 | B144: Julio | C144: Delantal y pimentero La Cautiva | D144: Otros Gastos | E144: =IF(ISBLANK(D144), "", VLOOKUP(D144, Config!$F$6:$G$30, 2, FALSE())) -> Variable | F144: 86300 | G144: Efectivo/MP
A145: 46192 | B145: Julio | C145: Verdulería para comida con autorespeto | D145: Salidas / Gastronomía | E145: =IF(ISBLANK(D145), "", VLOOKUP(D145, Config!$F$6:$G$30, 2, FALSE())) -> Variable | F145: 13468 | G145: Efectivo/MP
A146: 46223 | B146: Julio | C146: Cumple Lantu con las chicas | D146: Otros Gastos | E146: =IF(ISBLANK(D146), "", VLOOKUP(D146, Config!$F$6:$G$30, 2, FALSE())) -> Variable | F146: 3800 | G146: Efectivo/MP
A147: 46224 | B147: Julio | C147: Viaje Brasil con el Tomi en octubre | D147: Compras Online / Impulsivas | E147: =IF(ISBLANK(D147), "", VLOOKUP(D147, Config!$F$6:$G$30, 2, FALSE())) -> Variable | F147: 1936500 | G147: Tarjeta de Crédito
A148: 46221 | B148: Julio | C148: Cuota colegio junio | D148: Profesional (Colegiatura) | E148: =IF(ISBLANK(D148), "", VLOOKUP(D148, Config!$F$6:$G$30, 2, FALSE())) -> Fijo | F148: 38340 | G148: Tarjeta de Crédito
A149: 46221 | B149: Julio | C149: Merienda con el Tomi | D149: Salidas / Gastronomía | E149: =IF(ISBLANK(D149), "", VLOOKUP(D149, Config!$F$6:$G$30, 2, FALSE())) -> Variable | F149: 28000 | G149: Tarjeta de Crédito
A150: 46220 | B150: Julio | C150: Airsat Julio 26 | D150: Internet | E150: =IF(ISBLANK(D150), "", VLOOKUP(D150, Config!$F$6:$G$30, 2, FALSE())) -> Fijo | F150: 37500 | G150: Tarjeta de Crédito
A151: 46219 | B151: Julio | C151: Silent Hill 2 xbox | D151: Otros Gastos | E151: =IF(ISBLANK(D151), "", VLOOKUP(D151, Config!$F$6:$G$30, 2, FALSE())) -> Variable | F151: 33000 | G151: Tarjeta de Crédito
...

Sheet Dashboard
A1: DASHBOARD ANUAL INTELIGENTE
A2: Seleccione un mes para el análisis local. A la derecha verá el comportamiento histórico consolidado.
A4: Mes de Análisis: | B4: Agosto | J4: HISTORIAL ANUAL CONSOLIDADO
J5: Mes | K5: Ingresos ($) | L5: Gastos ($) | M5: Ahorro Real ($) | N5: Tasa de Ahorro
A6: INGRESOS DEL MES | D6: GASTOS DEL MES | G6: SALDO NETO (AHORRO REAL) | J6: Enero | K6: =SUMIF(Ingresos!$B$5:$B$1004, J6, Ingresos!$E$5:$E$1004) -> 0 | L6: =SUMIF(Gastos!$B$5:$B$2004, J6, Gastos!$F$5:$F$2004) -> 0 | M6: =K6-L6 -> 0 | N6: =IF(K6=0, 0, M6/K6) -> 0
A7: =SUMIFS(Ingresos!$E:$E, Ingresos!$B:$B, $B$4) -> 2771000 | D7: =SUMIFS(Gastos!$F:$F, Gastos!$B:$B, $B$4) -> 4537220 | G7: =A7-D7 -> -1766220 | J7: Febrero | K7: =SUMIF(Ingresos!$B$5:$B$1004, J7, Ingresos!$E$5:$E$1004) -> 0 | L7: =SUMIF(Gastos!$B$5:$B$2004, J7, Gastos!$F$5:$F$2004) -> 0 | M7: =K7-L7 -> 0 | N7: =IF(K7=0, 0, M7/K7) -> 0
J8: Marzo | K8: =SUMIF(Ingresos!$B$5:$B$1004, J8, Ingresos!$E$5:$E$1004) -> 0 | L8: =SUMIF(Gastos!$B$5:$B$2004, J8, Gastos!$F$5:$F$2004) -> 0 | M8: =K8-L8 -> 0 | N8: =IF(K8=0, 0, M8/K8) -> 0
J9: Abril | K9: =SUMIF(Ingresos!$B$5:$B$1004, J9, Ingresos!$E$5:$E$1004) -> 1905000 | L9: =SUMIF(Gastos!$B$5:$B$2004, J9, Gastos!$F$5:$F$2004) -> 1245495.5 | M9: =K9-L9 -> 659504.46 | N9: =IF(K9=0, 0, M9/K9) -> 0.34619657
A10: Cumplimiento del Plan Presupuestario | J10: Mayo | K10: =SUMIF(Ingresos!$B$5:$B$1004, J10, Ingresos!$E$5:$E$1004) -> 2280000 | L10: =SUMIF(Gastos!$B$5:$B$2004, J10, Gastos!$F$5:$F$2004) -> 1831913.7 | M10: =K10-L10 -> 448086.26 | N10: =IF(K10=0, 0, M10/K10) -> 0.19652906
A11: Línea Presupuestaria | B11: % Planificado | C11: Monto Estimado ($) | D11: Gasto/Ahorro Real ($) | E11: Diferencia ($) | F11: Estado | J11: Junio | K11: =SUMIF(Ingresos!$B$5:$B$1004, J11, Ingresos!$E$5:$E$1004) -> 2305000 | L11: =SUMIF(Gastos!$B$5:$B$2004, J11, Gastos!$F$5:$F$2004) -> 1886480.2 | M11: =K11-L11 -> 418519.76 | N11: =IF(K11=0, 0, M11/K11) -> 0.18157039
A12: Gastos Fijos (Necesidades) | B12: =Config!B6 -> 0.5 | C12: =B12*$A$7 -> 1385500 | D12: =SUMIFS(Gastos!$F$5:$F$2004, Gastos!$B$5:$B$2004, $B$4, Gastos!$E$5:$E$2004, "Fijo") -> 1400000 | E12: =C12-D12 -> -14500 | F12: =IF(E12>=0, "🟢 Dentro de Límite", "🔴 Excedido") -> 🔴 Excedido | J12: Julio | K12: =SUMIF(Ingresos!$B$5:$B$1004, J12, Ingresos!$E$5:$E$1004) -> 4189930 | L12: =SUMIF(Gastos!$B$5:$B$2004, J12, Gastos!$F$5:$F$2004) -> 8122844 | M12: =K12-L12 -> -3932914 | N12: =IF(K12=0, 0, M12/K12) -> -0.93865864
A13: Gastos Variables (Deseos) | B13: =Config!B7 -> 0.3 | C13: =B13*$A$7 -> 831300 | D13: =SUMIFS(Gastos!$F$5:$F$2004, Gastos!$B$5:$B$2004, $B$4, Gastos!$E$5:$E$2004, "Variable") -> 144500 | E13: =C13-D13 -> 686800 | F13: =IF(E13>=0, "🟢 Dentro de Límite", "🔴 Excedido") -> 🟢 Dentro de Límite | J13: Agosto | K13: =SUMIF(Ingresos!$B$5:$B$1004, J13, Ingresos!$E$5:$E$1004) -> 2771000 | L13: =SUMIF(Gastos!$B$5:$B$2004, J13, Gastos!$F$5:$F$2004) -> 4537220 | M13: =K13-L13 -> -1766220 | N13: =IF(K13=0, 0, M13/K13) -> -0.63739444
A14: Ahorro / Inversión | B14: =Config!B8 -> 0.2 | C14: =B14*$A$7 -> 554200 | D14: =G7 -> -1766220 | E14: =D14-C14 -> -2320420 | F14: =IF(E14>=0, "🟢 Meta Alcanzada", "🔴 Bajo la Meta") -> 🔴 Bajo la Meta | J14: Septiembre | K14: =SUMIF(Ingresos!$B$5:$B$1004, J14, Ingresos!$E$5:$E$1004) -> 0 | L14: =SUMIF(Gastos!$B$5:$B$2004, J14, Gastos!$F$5:$F$2004) -> 0 | M14: =K14-L14 -> 0 | N14: =IF(K14=0, 0, M14/K14) -> 0
J15: Octubre | K15: =SUMIF(Ingresos!$B$5:$B$1004, J15, Ingresos!$E$5:$E$1004) -> 0 | L15: =SUMIF(Gastos!$B$5:$B$2004, J15, Gastos!$F$5:$F$2004) -> 0 | M15: =K15-L15 -> 0 | N15: =IF(K15=0, 0, M15/K15) -> 0
J16: Noviembre | K16: =SUMIF(Ingresos!$B$5:$B$1004, J16, Ingresos!$E$5:$E$1004) -> 0 | L16: =SUMIF(Gastos!$B$5:$B$2004, J16, Gastos!$F$5:$F$2004) -> 0 | M16: =K16-L16 -> 0 | N16: =IF(K16=0, 0, M16/K16) -> 0
A17: Desglose por Categoría de Gastos | J17: Diciembre | K17: =SUMIF(Ingresos!$B$5:$B$1004, J17, Ingresos!$E$5:$E$1004) -> 0 | L17: =SUMIF(Gastos!$B$5:$B$2004, J17, Gastos!$F$5:$F$2004) -> 0 | M17: =K17-L17 -> 0 | N17: =IF(K17=0, 0, M17/K17) -> 0
A18: Categoría | B18: Total Gastado ($) | C18: Porcentaje del total (%) | J18: Total Anual: | K18: =SUM(K6:K17) -> 13450930 | L18: =SUM(L6:L17) -> 17623954 | M18: =SUM(M6:M17) -> -4173023.5 | N18: =IF(K18=0, 0, M18/K18) -> -0.31024052
A19: =Config!F6 -> Expensas | B19: =SUMIFS('Respuestas de formulario 1'!$G:$G, 'Respuestas de formulario 1'!$C:$C, $B$4, 'Respuestas de formulario 1'!$D:$D, "Gasto", 'Respuestas de formulario 1'!$E:$E, A19) -> 0 | C19: =IFERROR(B19/$B$40, 0) -> 0
A20: =Config!F7 -> Prepaga | B20: =SUMIFS(Gastos!$F$5:$F$2004, Gastos!$B$5:$B$2004, $B$4, Gastos!$D$5:$D$2004, A20) -> 0 | C20: =IFERROR(B20/$B$40, 0) -> 0
A21: =Config!F8 -> Monotributo | B21: =SUMIFS(Gastos!$F$5:$F$2004, Gastos!$B$5:$B$2004, $B$4, Gastos!$D$5:$D$2004, A21) -> 0 | C21: =IFERROR(B21/$B$40, 0) -> 0
A22: =Config!F9 -> Seguro Auto | B22: =SUMIFS(Gastos!$F$5:$F$2004, Gastos!$B$5:$B$2004, $B$4, Gastos!$D$5:$D$2004, A22) -> 0 | C22: =IFERROR(B22/$B$40, 0) -> 0
A23: =Config!F10 -> Seguros Adicionales | B23: =SUMIFS(Gastos!$F$5:$F$2004, Gastos!$B$5:$B$2004, $B$4, Gastos!$D$5:$D$2004, A23) -> 0 | C23: =IFERROR(B23/$B$40, 0) -> 0
A24: =Config!F11 -> Luz | B24: =SUMIFS(Gastos!$F$5:$F$2004, Gastos!$B$5:$B$2004, $B$4, Gastos!$D$5:$D$2004, A24) -> 0 | C24: =IFERROR(B24/$B$40, 0) -> 0
A25: =Config!F12 -> Agua | B25: =SUMIFS(Gastos!$F$5:$F$2004, Gastos!$B$5:$B$2004, $B$4, Gastos!$D$5:$D$2004, A25) -> 0 | C25: =IFERROR(B25/$B$40, 0) -> 0
A26: =Config!F13 -> Gas | B26: =SUMIFS(Gastos!$F$5:$F$2004, Gastos!$B$5:$B$2004, $B$4, Gastos!$D$5:$D$2004, A26) -> 0 | C26: =IFERROR(B26/$B$40, 0) -> 0
A27: =Config!F14 -> Internet | B27: =SUMIFS(Gastos!$F$5:$F$2004, Gastos!$B$5:$B$2004, $B$4, Gastos!$D$5:$D$2004, A27) -> 0 | C27: =IFERROR(B27/$B$40, 0) -> 0
A28: =Config!F15 -> Telefonía | B28: =SUMIFS(Gastos!$F$5:$F$2004, Gastos!$B$5:$B$2004, $B$4, Gastos!$D$5:$D$2004, A28) -> 0 | C28: =IFERROR(B28/$B$40, 0) -> 0
A29: =Config!F16 -> Transporte / Auto | B29: =SUMIFS(Gastos!$F$5:$F$2004, Gastos!$B$5:$B$2004, $B$4, Gastos!$D$5:$D$2004, A29) -> 1400000 | C29: =IFERROR(B29/$B$40, 0) -> 0
A30: =Config!F17 -> Supermercado | B30: =SUMIFS(Gastos!$F$5:$F$2004, Gastos!$B$5:$B$2004, $B$4, Gastos!$D$5:$D$2004, A30) -> 0 | C30: =IFERROR(B30/$B$40, 0) -> 0
A31: =Config!F18 -> Mascota (Chancho) | B31: =SUMIFS(Gastos!$F$5:$F$2004, Gastos!$B$5:$B$2004, $B$4, Gastos!$D$5:$D$2004, A31) -> 0 | C31: =IFERROR(B31/$B$40, 0) -> 0
... A42: =Config!F29 -> Otros Gastos | B42: =SUMIFS(Gastos!$F$5:$F$2004, Gastos!$B$5:$B$2004, $B$4, Gastos!$D$5:$D$2004, A42) -> 83900 | C42: =IFERROR(B42/$B$40, 0) -> 0
A43: Total Consumos: | B43: =SUM(B19:B42) -> 1544500 | C43: =SUM(B19:B38) -> 1460600
A45: FLUJO DE CAJA REAL
A46: Esto no reemplaza el análisis por categoría de arriba (que registra gastos el día de la compra, para ver hábitos reales). Este panel responde otra pregunta: cuánta plata real tuviste disponible cada mes, incluyendo cuándo pagaste efectivamente el resumen de la tarjeta.
A47: Columnas C y D son manuales (celda azul): cargá el total que efectivamente pagaste de resumen de tarjeta ese mes, y cualquier otro gasto fuera de la tarjeta (efectivo, débito directo de servicios, etc.).
A49: Mes | B49: Ingresos del mes ($) | C49: Pago Resumen TC ($) | D49: Otros gastos fuera de TC ($) | E49: Saldo de Caja Real ($)
A50: =Config!I6 -> Enero | B50: =SUMIF(Ingresos!$B$5:$B$1004, A50, Ingresos!$E$5:$E$1004) -> 0 | C50: 0 | D50: =SUMIFS(Gastos!$F$5:$F$599, Gastos!$B$5:$B$599, A50, Gastos!$G$5:$G$599, "<>*Tarj*", Gastos!$D$5:$D$599, "<>Tarjeta") -> 0 | E50: =B50-C50-D50 -> 0
A51: =Config!I7 -> Febrero | B51: =SUMIF(Ingresos!$B$5:$B$1004, A51, Ingresos!$E$5:$E$1004) -> 0 | C51: 0 | D51: =SUMIFS(Gastos!$F$5:$F$599, Gastos!$B$5:$B$599, A51, Gastos!$G$5:$G$599, "<>*Tarj*", Gastos!$D$5:$D$599, "<>Tarjeta") -> 0 | E51: =B51-C51-D51 -> 0
A52: =Config!I8 -> Marzo | B52: =SUMIF(Ingresos!$B$5:$B$1004, A52, Ingresos!$E$5:$E$1004) -> 0 | C52: 0 | D52: =SUMIFS(Gastos!$F$5:$F$599, Gastos!$B$5:$B$599, A52, Gastos!$G$5:$G$599, "<>*Tarj*", Gastos!$D$5:$D$599, "<>Tarjeta") -> 0 | E52: =B52-C52-D52 -> 0
A53: =Config!I9 -> Abril | B53: =SUMIF(Ingresos!$B$5:$B$1004, A53, Ingresos!$E$5:$E$1004) -> 1905000 | C53: 0 | D53: =SUMIFS(Gastos!$F$5:$F$599, Gastos!$B$5:$B$599, A53, Gastos!$G$5:$G$599, "<>*Tarj*", Gastos!$D$5:$D$599, "<>Tarjeta") -> 0 | E53: =B53-C53-D53 -> 1905000
...
